2025-10-28 11:21:51.090 WARNING (SyncWorker_0) [homeassistant.loader] We found a custom integration spotifyplus which has not been tested by Home Assistant. This component might cause stability problems, be sure to disable it if you experience issues with Home Assistant
2025-10-28 11:21:51.095 WARNING (SyncWorker_0) [homeassistant.loader] We found a custom integration mail_and_packages which has not been tested by Home Assistant. This component might cause stability problems, be sure to disable it if you experience issues with Home Assistant
2025-10-28 11:21:51.099 WARNING (SyncWorker_0) [homeassistant.loader] We found a custom integration eufy_security which has not been tested by Home Assistant. This component might cause stability problems, be sure to disable it if you experience issues with Home Assistant
2025-10-28 11:21:51.102 WARNING (SyncWorker_0) [homeassistant.loader] We found a custom integration nest_protect which has not been tested by Home Assistant. This component might cause stability problems, be sure to disable it if you experience issues with Home Assistant
2025-10-28 11:21:51.105 WARNING (SyncWorker_0) [homeassistant.loader] We found a custom integration webrtc which has not been tested by Home Assistant. This component might cause stability problems, be sure to disable it if you experience issues with Home Assistant
2025-10-28 11:21:51.108 WARNING (SyncWorker_0) [homeassistant.loader] We found a custom integration watchman which has not been tested by Home Assistant. This component might cause stability problems, be sure to disable it if you experience issues with Home Assistant
2025-10-28 11:21:51.111 WARNING (SyncWorker_0) [homeassistant.loader] We found a custom integration roborock_custom_map which has not been tested by Home Assistant. This component might cause stability problems, be sure to disable it if you experience issues with Home Assistant
2025-10-28 11:21:51.114 WARNING (SyncWorker_0) [homeassistant.loader] We found a custom integration google_fit which has not been tested by Home Assistant. This component might cause stability problems, be sure to disable it if you experience issues with Home Assistant
2025-10-28 11:21:51.117 WARNING (SyncWorker_0) [homeassistant.loader] We found a custom integration openai_tts which has not been tested by Home Assistant. This component might cause stability problems, be sure to disable it if you experience issues with Home Assistant
2025-10-28 11:21:51.120 WARNING (SyncWorker_0) [homeassistant.loader] We found a custom integration google_home which has not been tested by Home Assistant. This component might cause stability problems, be sure to disable it if you experience issues with Home Assistant
2025-10-28 11:21:51.123 WARNING (SyncWorker_0) [homeassistant.loader] We found a custom integration better_thermostat which has not been tested by Home Assistant. This component might cause stability problems, be sure to disable it if you experience issues with Home Assistant
2025-10-28 11:21:51.130 WARNING (SyncWorker_0) [homeassistant.loader] We found a custom integration google_photos which has not been tested by Home Assistant. This component might cause stability problems, be sure to disable it if you experience issues with Home Assistant
2025-10-28 11:21:51.134 WARNING (SyncWorker_0) [homeassistant.loader] We found a custom integration spotcast which has not been tested by Home Assistant. This component might cause stability problems, be sure to disable it if you experience issues with Home Assistant
2025-10-28 11:21:51.141 WARNING (SyncWorker_0) [homeassistant.loader] We found a custom integration material_symbols which has not been tested by Home Assistant. This component might cause stability problems, be sure to disable it if you experience issues with Home Assistant
2025-10-28 11:21:51.144 WARNING (SyncWorker_0) [homeassistant.loader] We found a custom integration saver which has not been tested by Home Assistant. This component might cause stability problems, be sure to disable it if you experience issues with Home Assistant
2025-10-28 11:21:51.148 WARNING (SyncWorker_0) [homeassistant.loader] We found a custom integration hacs which has not been tested by Home Assistant. This component might cause stability problems, be sure to disable it if you experience issues with Home Assistant
2025-10-28 11:21:51.151 WARNING (SyncWorker_0) [homeassistant.loader] We found a custom integration ui_lovelace_minimalist which has not been tested by Home Assistant. This component might cause stability problems, be sure to disable it if you experience issues with Home Assistant
2025-10-28 11:21:51.154 WARNING (SyncWorker_0) [homeassistant.loader] We found a custom integration visonic which has not been tested by Home Assistant. This component might cause stability problems, be sure to disable it if you experience issues with Home Assistant
2025-10-28 11:21:51.158 WARNING (SyncWorker_0) [homeassistant.loader] We found a custom integration switch_manager which has not been tested by Home Assistant. This component might cause stability problems, be sure to disable it if you experience issues with Home Assistant
2025-10-28 11:21:54.247 WARNING (MainThread) [homeassistant.components.lovelace] Lovelace is running in storage mode. Define resources via user interface
2025-10-28 11:22:13.975 WARNING (ImportExecutor_0) [py.warnings] /usr/local/lib/python3.13/site-packages/sleekxmppfs/thirdparty/mini_dateutil.py:171: SyntaxWarning: invalid escape sequence '\s'
  (?:T|\s+)?

2025-10-28 11:22:15.969 WARNING (MainThread) [homeassistant.helpers.frame] Detected that custom integration 'webrtc' accessed lovelace_data['resources'] instead of lovelace_data.resources at custom_components/webrtc/utils.py, line 129: resources: ResourceStorageCollection = hass.data["lovelace"]["resources"]. This will stop working in Home Assistant 2026.2, please create a bug report at https://github.com/AlexxIT/WebRTC/issues
2025-10-28 11:22:38.509 WARNING (MainThread) [homeassistant.util.loop] Detected blocking call to open with args ('/root/.netrc',) inside the event loop by integration 'google_generative_ai_conversation' at homeassistant/components/google_generative_ai_conversation/__init__.py, line 165: await client.aio.models.get( (offender: /usr/local/lib/python3.13/netrc.py, line 87: with open(file, encoding="utf-8") as fp:), please create a bug report at https://github.com/home-assistant/core/issues?q=is%3Aopen+is%3Aissue+label%3A%22integration%3A+google_generative_ai_conversation%22
For developers, please see https://developers.home-assistant.io/docs/asyncio_blocking_operations/#open
Traceback (most recent call last):
  File "<frozen runpy>", line 198, in _run_module_as_main
  File "<frozen runpy>", line 88, in _run_code
  File "/usr/src/homeassistant/homeassistant/__main__.py", line 229, in <module>
    sys.exit(main())
  File "/usr/src/homeassistant/homeassistant/__main__.py", line 215, in main
    exit_code = runner.run(runtime_conf)
  File "/usr/src/homeassistant/homeassistant/runner.py", line 271, in run
    return loop.run_until_complete(setup_and_run_hass(runtime_config))
  File "/usr/local/lib/python3.13/asyncio/base_events.py", line 712, in run_until_complete
    self.run_forever()
  File "/usr/local/lib/python3.13/asyncio/base_events.py", line 683, in run_forever
    self._run_once()
  File "/usr/local/lib/python3.13/asyncio/base_events.py", line 2050, in _run_once
    handle._run()
  File "/usr/local/lib/python3.13/asyncio/events.py", line 89, in _run
    self._context.run(self._callback, *self._args)
  File "/usr/src/homeassistant/homeassistant/config_entries.py", line 906, in async_setup_locked
    await self.async_setup(hass, integration=integration)
  File "/usr/src/homeassistant/homeassistant/config_entries.py", line 672, in async_setup
    await self.__async_setup_with_context(hass, integration)
  File "/usr/src/homeassistant/homeassistant/config_entries.py", line 761, in __async_setup_with_context
    result = await component.async_setup_entry(hass, self)
  File "/usr/src/homeassistant/homeassistant/components/google_generative_ai_conversation/__init__.py", line 165, in async_setup_entry
    await client.aio.models.get(

2025-10-28 11:22:39.157 ERROR (MainThread) [homeassistant.config] Invalid config for 'template' at configuration.yaml, line 32: 'scan_interval' is an invalid option for 'template', check: sensor->0->scan_interval
2025-10-28 11:22:39.158 ERROR (MainThread) [homeassistant.config] Invalid config for 'template' at configuration.yaml, line 104: expected BinarySensorDeviceClass or one of 'battery', 'battery_charging', 'carbon_monoxide', 'cold', 'connectivity', 'door', 'garage_door', 'gas', 'heat', 'light', 'lock', 'moisture', 'motion', 'moving', 'occupancy', 'opening', 'plug', 'power', 'presence', 'problem', 'running', 'safety', 'smoke', 'sound', 'tamper', 'update', 'vibration', 'window' for dictionary value 'binary_sensor->0->device_class', got 'doorbell'
2025-10-28 11:22:53.635 ERROR (MainThread) [homeassistant.components.select] Platform tuya does not generate unique IDs. ID tuya.bf70484102653f9d216j6qrelay_status already exists - ignoring select.home_licht_verhalten_beim_einschalten
2025-10-28 11:22:53.635 ERROR (MainThread) [homeassistant.components.select] Platform tuya does not generate unique IDs. ID tuya.bf70484102653f9d216j6qlight_mode already exists - ignoring select.home_licht_modus_der_kontrollleuchte
2025-10-28 11:22:53.635 ERROR (MainThread) [homeassistant.components.select] Platform tuya does not generate unique IDs. ID tuya.bf471e1ae265ec4df6fywbrelay_status already exists - ignoring select.ldv_wifi_plug_verhalten_beim_einschalten
2025-10-28 11:22:53.643 ERROR (MainThread) [homeassistant.components.sensor] Platform tuya does not generate unique IDs. ID tuya.bf70484102653f9d216j6qadd_ele already exists - ignoring sensor.home_licht_energie_gesamt
2025-10-28 11:22:53.647 ERROR (MainThread) [homeassistant.components.sensor] Platform tuya does not generate unique IDs. ID tuya.bf471e1ae265ec4df6fywbadd_ele already exists - ignoring sensor.lichterkette_flur_energie_gesamt
2025-10-28 11:22:53.648 ERROR (MainThread) [homeassistant.components.switch] Platform tuya does not generate unique IDs. ID tuya.bf70484102653f9d216j6qswitch_1 already exists - ignoring switch.home_licht_steckdose_1
2025-10-28 11:22:53.658 ERROR (MainThread) [homeassistant.components.switch] Platform tuya does not generate unique IDs. ID tuya.bf471e1ae265ec4df6fywbswitch_1 already exists - ignoring switch.ldv_wifi_plug_steckdose_1
2025-10-28 11:22:57.958 ERROR (MainThread) [homeassistant.components.google_cloud.tts] Error from calling list_voices: 403 Cloud Text-to-Speech API has not been used in project 436058902374 before or it is disabled. Enable it by visiting https://console.developers.google.com/apis/api/texttospeech.googleapis.com/overview?project=436058902374 then retry. If you enabled this API recently, wait a few minutes for the action to propagate to our systems and retry. [reason: "SERVICE_DISABLED"
domain: "googleapis.com"
metadata {
  key: "service"
  value: "texttospeech.googleapis.com"
}
metadata {
  key: "serviceTitle"
  value: "Cloud Text-to-Speech API"
}
metadata {
  key: "containerInfo"
  value: "436058902374"
}
metadata {
  key: "consumer"
  value: "projects/436058902374"
}
metadata {
  key: "activationUrl"
  value: "https://console.developers.google.com/apis/api/texttospeech.googleapis.com/overview?project=436058902374"
}
, locale: "en-US"
message: "Cloud Text-to-Speech API has not been used in project 436058902374 before or it is disabled. Enable it by visiting https://console.developers.google.com/apis/api/texttospeech.googleapis.com/overview?project=436058902374 then retry. If you enabled this API recently, wait a few minutes for the action to propagate to our systems and retry."
, links {
  description: "Google developers console API activation"
  url: "https://console.developers.google.com/apis/api/texttospeech.googleapis.com/overview?project=436058902374"
}
]
2025-10-28 11:23:00.570 WARNING (MainThread) [homeassistant.bootstrap] Waiting on integrations to complete setup: {('better_thermostat', '01K3439Y9EHVKY8ETNJV720V0K'): 1987054.882157385, ('google_tasks', '01JEDQC3SNHMVNHD0YPH0FHQBR'): 1987080.516195716, ('google_photos', '01JEDQ6E7WSF4BRARDVTH79FGP'): 1987080.550063213, ('google_mail', '01JEDQMDKP7WP0HNXZ4J74DTCM'): 1987080.647173464, ('google', '01JEDQR8QXJ927RZ24PZ3J4QD1'): 1987089.301921334, ('spotify', '01K114K7YV78TQZJRFD95TDW5J'): 1987091.751524422, ('google_fit', '01JEDR3ZYMT7B1T6463QAWABHX'): 1987091.89756396, ('homeassistant_sky_connect', '01K2WVBP8ZKCW55AF2KE59V0GH'): 1987094.701410672}
2025-10-28 11:23:03.932 WARNING (SyncWorker_8) [googleapiclient.http] Encountered 403 Forbidden with reason "PERMISSION_DENIED"
2025-10-28 11:23:04.171 ERROR (MainThread) [homeassistant.helpers.entity_platform] google_photos raises exception ConfigEntryNotReady in forwarded platform camera; Instead raise ConfigEntryNotReady before calling async_forward_entry_setups
2025-10-28 11:23:04.171 ERROR (MainThread) [homeassistant.helpers.entity_platform] google_photos raises exception ConfigEntryNotReady in forwarded platform sensor; Instead raise ConfigEntryNotReady before calling async_forward_entry_setups
2025-10-28 11:23:04.172 ERROR (MainThread) [homeassistant.helpers.entity_platform] google_photos raises exception ConfigEntryNotReady in forwarded platform select; Instead raise ConfigEntryNotReady before calling async_forward_entry_setups
2025-10-28 11:23:13.329 ERROR (MainThread) [homeassistant] Error doing job: Task exception was never retrieved (None)
Traceback (most recent call last):
  File "/usr/src/homeassistant/homeassistant/components/cloud/alexa_config.py", line 330, in async_get_access_token
    details = await self._cloud.alexa_api.access_token()
              ^^^^^^^^^^^^^^^^^^^^^^^^^^^^^^^^^^^^^^^^^^
  File "/usr/local/lib/python3.13/site-packages/hass_nabucasa/api.py", line 58, in wrapper
    return await func(*args, **kwargs)
           ^^^^^^^^^^^^^^^^^^^^^^^^^^^
  File "/usr/local/lib/python3.13/site-packages/hass_nabucasa/alexa_api.py", line 63, in access_token
    raise AlexaApiNeedsRelinkError(
    ...<3 lines>...
    ) from None
hass_nabucasa.alexa_api.AlexaApiNeedsRelinkError: RefreshTokenNotFound

The above exception was the direct cause of the following exception:

Traceback (most recent call last):
  File "/usr/src/homeassistant/homeassistant/components/cloud/alexa_config.py", line 550, in _handle_entity_registry_updated
    await self._sync_helper(to_update, to_remove)
  File "/usr/src/homeassistant/homeassistant/components/cloud/alexa_config.py", line 490, in _sync_helper
    await self.async_get_access_token()
  File "/usr/src/homeassistant/homeassistant/components/cloud/alexa_config.py", line 343, in async_get_access_token
    raise alexa_errors.RequireRelink from exception
homeassistant.components.alexa.errors.RequireRelink
2025-10-28 11:23:13.581 ERROR (MainThread) [homeassistant.components.google_travel_time.sensor] Routes API is disabled for this API key
2025-10-28 11:23:15.706 WARNING (Recorder) [homeassistant.components.recorder.db_schema] State attributes for sensor.bubble_card_modules exceed maximum size of 16384 bytes. This can cause database performance issues; Attributes will not be stored
2025-10-28 11:23:17.931 WARNING (Recorder) [homeassistant.components.recorder.db_schema] State attributes for sensor.bubble_card_modules exceed maximum size of 16384 bytes. This can cause database performance issues; Attributes will not be stored
2025-10-28 11:23:18.193 ERROR (SyncWorker_0) [homeassistant.util.package] Unable to install package urllib3>=1.21.1,<1.27: × No solution found when resolving dependencies:
  ╰─▶ Because you require urllib3>=1.21.1,<1.27 and urllib3>=2.0, we can
      conclude that your requirements are unsatisfiable.
2025-10-28 11:23:19.886 ERROR (SyncWorker_0) [homeassistant.util.package] Unable to install package urllib3>=1.21.1,<1.27: × No solution found when resolving dependencies:
  ╰─▶ Because you require urllib3>=1.21.1,<1.27 and urllib3>=2.0, we can
      conclude that your requirements are unsatisfiable.
2025-10-28 11:23:20.511 ERROR (SyncWorker_0) [homeassistant.util.package] Unable to install package urllib3>=1.21.1,<1.27: × No solution found when resolving dependencies:
  ╰─▶ Because you require urllib3>=1.21.1,<1.27 and urllib3>=2.0, we can
      conclude that your requirements are unsatisfiable.
2025-10-28 11:23:20.594 ERROR (MainThread) [homeassistant] Error doing job: Task exception was never retrieved (None)
Traceback (most recent call last):
  File "/usr/src/homeassistant/homeassistant/helpers/discovery_flow.py", line 137, in _async_start
    await gather_with_limited_concurrency(FLOW_INIT_LIMIT, *init_coros)
  File "/usr/src/homeassistant/homeassistant/util/async_.py", line 113, in gather_with_limited_concurrency
    return await gather(
           ^^^^^^^^^^^^^
    ...<2 lines>...
    )
    ^
  File "/usr/src/homeassistant/homeassistant/util/async_.py", line 111, in sem_task
    return await task
           ^^^^^^^^^^
  File "/usr/src/homeassistant/homeassistant/config_entries.py", line 1464, in async_init
    flow, result = await self._async_init(flow_id, handler, context, data)
                   ^^^^^^^^^^^^^^^^^^^^^^^^^^^^^^^^^^^^^^^^^^^^^^^^^^^^^^^
  File "/usr/src/homeassistant/homeassistant/config_entries.py", line 1500, in _async_init
    flow = await self.async_create_flow(handler, context=context, data=data)
           ^^^^^^^^^^^^^^^^^^^^^^^^^^^^^^^^^^^^^^^^^^^^^^^^^^^^^^^^^^^^^^^^^
  File "/usr/src/homeassistant/homeassistant/config_entries.py", line 1722, in async_create_flow
    handler = await _async_get_flow_handler(
              ^^^^^^^^^^^^^^^^^^^^^^^^^^^^^^
        self.hass, handler_key, self._hass_config
        ^^^^^^^^^^^^^^^^^^^^^^^^^^^^^^^^^^^^^^^^^
    )
    ^
  File "/usr/src/homeassistant/homeassistant/config_entries.py", line 3871, in _async_get_flow_handler
    await _load_integration(hass, domain, hass_config)
  File "/usr/src/homeassistant/homeassistant/config_entries.py", line 3848, in _load_integration
    await async_process_deps_reqs(hass, hass_config, integration)
  File "/usr/src/homeassistant/homeassistant/setup.py", line 584, in async_process_deps_reqs
    await requirements.async_get_integration_with_requirements(
        hass, integration.domain
    )
  File "/usr/src/homeassistant/homeassistant/requirements.py", line 54, in async_get_integration_with_requirements
    return await manager.async_get_integration_with_requirements(domain)
           ^^^^^^^^^^^^^^^^^^^^^^^^^^^^^^^^^^^^^^^^^^^^^^^^^^^^^^^^^^^^^
  File "/usr/src/homeassistant/homeassistant/requirements.py", line 170, in async_get_integration_with_requirements
    await future
  File "/usr/src/homeassistant/homeassistant/requirements.py", line 159, in async_get_integration_with_requirements
    await self._async_process_integration(integration, done)
  File "/usr/src/homeassistant/homeassistant/requirements.py", line 182, in _async_process_integration
    await self.async_process_requirements(
        integration.domain, integration.requirements
    )
  File "/usr/src/homeassistant/homeassistant/requirements.py", line 269, in async_process_requirements
    await self._async_process_requirements(name, missing)
  File "/usr/src/homeassistant/homeassistant/requirements.py", line 307, in _async_process_requirements
    raise RequirementsNotFound(name, list(failures))
homeassistant.requirements.RequirementsNotFound: Requirements for spotifyplus not found: ['urllib3>=1.21.1,<1.27'].
2025-10-28 11:23:25.565 WARNING (ImportExecutor_0) [py.warnings] /usr/local/lib/python3.13/site-packages/fritzconnection/core/soaper.py:207: SyntaxWarning: invalid escape sequence '\d'
  wifi_pwd_keys = 'New(WEPKey\d+|PreSharedKey|KeyPassphrase)'

2025-10-28 11:32:57.963 ERROR (MainThread) [homeassistant.components.google_travel_time.sensor] Routes API is disabled for this API key
2025-10-28 11:36:33.887 ERROR (MainThread) [homeassistant] Error doing job: Task exception was never retrieved (None)
Traceback (most recent call last):
  File "/usr/src/homeassistant/homeassistant/config_entries.py", line 1464, in async_init
    flow, result = await self._async_init(flow_id, handler, context, data)
                   ^^^^^^^^^^^^^^^^^^^^^^^^^^^^^^^^^^^^^^^^^^^^^^^^^^^^^^^
  File "/usr/src/homeassistant/homeassistant/config_entries.py", line 1500, in _async_init
    flow = await self.async_create_flow(handler, context=context, data=data)
           ^^^^^^^^^^^^^^^^^^^^^^^^^^^^^^^^^^^^^^^^^^^^^^^^^^^^^^^^^^^^^^^^^
  File "/usr/src/homeassistant/homeassistant/config_entries.py", line 1722, in async_create_flow
    handler = await _async_get_flow_handler(
              ^^^^^^^^^^^^^^^^^^^^^^^^^^^^^^
        self.hass, handler_key, self._hass_config
        ^^^^^^^^^^^^^^^^^^^^^^^^^^^^^^^^^^^^^^^^^
    )
    ^
  File "/usr/src/homeassistant/homeassistant/config_entries.py", line 3871, in _async_get_flow_handler
    await _load_integration(hass, domain, hass_config)
  File "/usr/src/homeassistant/homeassistant/config_entries.py", line 3848, in _load_integration
    await async_process_deps_reqs(hass, hass_config, integration)
  File "/usr/src/homeassistant/homeassistant/setup.py", line 584, in async_process_deps_reqs
    await requirements.async_get_integration_with_requirements(
        hass, integration.domain
    )
  File "/usr/src/homeassistant/homeassistant/requirements.py", line 54, in async_get_integration_with_requirements
    return await manager.async_get_integration_with_requirements(domain)
           ^^^^^^^^^^^^^^^^^^^^^^^^^^^^^^^^^^^^^^^^^^^^^^^^^^^^^^^^^^^^^
  File "/usr/src/homeassistant/homeassistant/requirements.py", line 170, in async_get_integration_with_requirements
    await future
  File "/usr/src/homeassistant/homeassistant/requirements.py", line 159, in async_get_integration_with_requirements
    await self._async_process_integration(integration, done)
  File "/usr/src/homeassistant/homeassistant/requirements.py", line 182, in _async_process_integration
    await self.async_process_requirements(
        integration.domain, integration.requirements
    )
  File "/usr/src/homeassistant/homeassistant/requirements.py", line 264, in async_process_requirements
    self._raise_for_failed_requirements(name, missing)
    ~~~~~~~~~~~~~~~~~~~~~~~~~~~~~~~~~~~^^^^^^^^^^^^^^^
  File "/usr/src/homeassistant/homeassistant/requirements.py", line 292, in _raise_for_failed_requirements
    raise RequirementsNotFound(integration, [req])
homeassistant.requirements.RequirementsNotFound: Requirements for spotifyplus not found: ['urllib3>=1.21.1,<1.27'].
2025-10-28 11:42:57.961 ERROR (MainThread) [homeassistant.components.google_travel_time.sensor] Routes API is disabled for this API key
2025-10-28 11:50:04.002 ERROR (SyncWorker_2) [homeassistant] Error doing job: Task exception was never retrieved (None)
Traceback (most recent call last):
  File "/usr/src/homeassistant/homeassistant/config_entries.py", line 1464, in async_init
    flow, result = await self._async_init(flow_id, handler, context, data)
                   ^^^^^^^^^^^^^^^^^^^^^^^^^^^^^^^^^^^^^^^^^^^^^^^^^^^^^^^
  File "/usr/src/homeassistant/homeassistant/config_entries.py", line 1500, in _async_init
    flow = await self.async_create_flow(handler, context=context, data=data)
           ^^^^^^^^^^^^^^^^^^^^^^^^^^^^^^^^^^^^^^^^^^^^^^^^^^^^^^^^^^^^^^^^^
  File "/usr/src/homeassistant/homeassistant/config_entries.py", line 1722, in async_create_flow
    handler = await _async_get_flow_handler(
              ^^^^^^^^^^^^^^^^^^^^^^^^^^^^^^
        self.hass, handler_key, self._hass_config
        ^^^^^^^^^^^^^^^^^^^^^^^^^^^^^^^^^^^^^^^^^
    )
    ^
  File "/usr/src/homeassistant/homeassistant/config_entries.py", line 3871, in _async_get_flow_handler
    await _load_integration(hass, domain, hass_config)
  File "/usr/src/homeassistant/homeassistant/config_entries.py", line 3848, in _load_integration
    await async_process_deps_reqs(hass, hass_config, integration)
  File "/usr/src/homeassistant/homeassistant/setup.py", line 584, in async_process_deps_reqs
    await requirements.async_get_integration_with_requirements(
        hass, integration.domain
    )
  File "/usr/src/homeassistant/homeassistant/requirements.py", line 54, in async_get_integration_with_requirements
    return await manager.async_get_integration_with_requirements(domain)
           ^^^^^^^^^^^^^^^^^^^^^^^^^^^^^^^^^^^^^^^^^^^^^^^^^^^^^^^^^^^^^
  File "/usr/src/homeassistant/homeassistant/requirements.py", line 170, in async_get_integration_with_requirements
    await future
  File "/usr/src/homeassistant/homeassistant/requirements.py", line 159, in async_get_integration_with_requirements
    await self._async_process_integration(integration, done)
  File "/usr/src/homeassistant/homeassistant/requirements.py", line 182, in _async_process_integration
    await self.async_process_requirements(
        integration.domain, integration.requirements
    )
  File "/usr/src/homeassistant/homeassistant/requirements.py", line 264, in async_process_requirements
    self._raise_for_failed_requirements(name, missing)
    ~~~~~~~~~~~~~~~~~~~~~~~~~~~~~~~~~~~^^^^^^^^^^^^^^^
  File "/usr/src/homeassistant/homeassistant/requirements.py", line 292, in _raise_for_failed_requirements
    raise RequirementsNotFound(integration, [req])
homeassistant.requirements.RequirementsNotFound: Requirements for spotifyplus not found: ['urllib3>=1.21.1,<1.27'].
2025-10-28 11:52:57.960 ERROR (MainThread) [homeassistant.components.google_travel_time.sensor] Routes API is disabled for this API key
2025-10-28 11:56:55.178 ERROR (MainThread) [homeassistant] Error doing job: Task exception was never retrieved (None)
Traceback (most recent call last):
  File "/usr/src/homeassistant/homeassistant/config_entries.py", line 1464, in async_init
    flow, result = await self._async_init(flow_id, handler, context, data)
                   ^^^^^^^^^^^^^^^^^^^^^^^^^^^^^^^^^^^^^^^^^^^^^^^^^^^^^^^
  File "/usr/src/homeassistant/homeassistant/config_entries.py", line 1500, in _async_init
    flow = await self.async_create_flow(handler, context=context, data=data)
           ^^^^^^^^^^^^^^^^^^^^^^^^^^^^^^^^^^^^^^^^^^^^^^^^^^^^^^^^^^^^^^^^^
  File "/usr/src/homeassistant/homeassistant/config_entries.py", line 1722, in async_create_flow
    handler = await _async_get_flow_handler(
              ^^^^^^^^^^^^^^^^^^^^^^^^^^^^^^
        self.hass, handler_key, self._hass_config
        ^^^^^^^^^^^^^^^^^^^^^^^^^^^^^^^^^^^^^^^^^
    )
    ^
  File "/usr/src/homeassistant/homeassistant/config_entries.py", line 3871, in _async_get_flow_handler
    await _load_integration(hass, domain, hass_config)
  File "/usr/src/homeassistant/homeassistant/config_entries.py", line 3848, in _load_integration
    await async_process_deps_reqs(hass, hass_config, integration)
  File "/usr/src/homeassistant/homeassistant/setup.py", line 584, in async_process_deps_reqs
    await requirements.async_get_integration_with_requirements(
        hass, integration.domain
    )
  File "/usr/src/homeassistant/homeassistant/requirements.py", line 54, in async_get_integration_with_requirements
    return await manager.async_get_integration_with_requirements(domain)
           ^^^^^^^^^^^^^^^^^^^^^^^^^^^^^^^^^^^^^^^^^^^^^^^^^^^^^^^^^^^^^
  File "/usr/src/homeassistant/homeassistant/requirements.py", line 170, in async_get_integration_with_requirements
    await future
  File "/usr/src/homeassistant/homeassistant/requirements.py", line 159, in async_get_integration_with_requirements
    await self._async_process_integration(integration, done)
  File "/usr/src/homeassistant/homeassistant/requirements.py", line 182, in _async_process_integration
    await self.async_process_requirements(
        integration.domain, integration.requirements
    )
  File "/usr/src/homeassistant/homeassistant/requirements.py", line 264, in async_process_requirements
    self._raise_for_failed_requirements(name, missing)
    ~~~~~~~~~~~~~~~~~~~~~~~~~~~~~~~~~~~^^^^^^^^^^^^^^^
  File "/usr/src/homeassistant/homeassistant/requirements.py", line 292, in _raise_for_failed_requirements
    raise RequirementsNotFound(integration, [req])
homeassistant.requirements.RequirementsNotFound: Requirements for spotifyplus not found: ['urllib3>=1.21.1,<1.27'].
2025-10-28 12:02:57.956 ERROR (MainThread) [homeassistant.components.google_travel_time.sensor] Routes API is disabled for this API key
2025-10-28 12:11:55.207 ERROR (MainThread) [homeassistant] Error doing job: Task exception was never retrieved (None)
Traceback (most recent call last):
  File "/usr/src/homeassistant/homeassistant/config_entries.py", line 1464, in async_init
    flow, result = await self._async_init(flow_id, handler, context, data)
                   ^^^^^^^^^^^^^^^^^^^^^^^^^^^^^^^^^^^^^^^^^^^^^^^^^^^^^^^
  File "/usr/src/homeassistant/homeassistant/config_entries.py", line 1500, in _async_init
    flow = await self.async_create_flow(handler, context=context, data=data)
           ^^^^^^^^^^^^^^^^^^^^^^^^^^^^^^^^^^^^^^^^^^^^^^^^^^^^^^^^^^^^^^^^^
  File "/usr/src/homeassistant/homeassistant/config_entries.py", line 1722, in async_create_flow
    handler = await _async_get_flow_handler(
              ^^^^^^^^^^^^^^^^^^^^^^^^^^^^^^
        self.hass, handler_key, self._hass_config
        ^^^^^^^^^^^^^^^^^^^^^^^^^^^^^^^^^^^^^^^^^
    )
    ^
  File "/usr/src/homeassistant/homeassistant/config_entries.py", line 3871, in _async_get_flow_handler
    await _load_integration(hass, domain, hass_config)
  File "/usr/src/homeassistant/homeassistant/config_entries.py", line 3848, in _load_integration
    await async_process_deps_reqs(hass, hass_config, integration)
  File "/usr/src/homeassistant/homeassistant/setup.py", line 584, in async_process_deps_reqs
    await requirements.async_get_integration_with_requirements(
        hass, integration.domain
    )
  File "/usr/src/homeassistant/homeassistant/requirements.py", line 54, in async_get_integration_with_requirements
    return await manager.async_get_integration_with_requirements(domain)
           ^^^^^^^^^^^^^^^^^^^^^^^^^^^^^^^^^^^^^^^^^^^^^^^^^^^^^^^^^^^^^
  File "/usr/src/homeassistant/homeassistant/requirements.py", line 170, in async_get_integration_with_requirements
    await future
  File "/usr/src/homeassistant/homeassistant/requirements.py", line 159, in async_get_integration_with_requirements
    await self._async_process_integration(integration, done)
  File "/usr/src/homeassistant/homeassistant/requirements.py", line 182, in _async_process_integration
    await self.async_process_requirements(
        integration.domain, integration.requirements
    )
  File "/usr/src/homeassistant/homeassistant/requirements.py", line 264, in async_process_requirements
    self._raise_for_failed_requirements(name, missing)
    ~~~~~~~~~~~~~~~~~~~~~~~~~~~~~~~~~~~^^^^^^^^^^^^^^^
  File "/usr/src/homeassistant/homeassistant/requirements.py", line 292, in _raise_for_failed_requirements
    raise RequirementsNotFound(integration, [req])
homeassistant.requirements.RequirementsNotFound: Requirements for spotifyplus not found: ['urllib3>=1.21.1,<1.27'].
2025-10-28 12:12:57.965 ERROR (MainThread) [homeassistant.components.google_travel_time.sensor] Routes API is disabled for this API key
2025-10-28 12:21:21.567 ERROR (SyncWorker_5) [homeassistant] Error doing job: Task exception was never retrieved (None)
Traceback (most recent call last):
  File "/usr/src/homeassistant/homeassistant/config_entries.py", line 1464, in async_init
    flow, result = await self._async_init(flow_id, handler, context, data)
                   ^^^^^^^^^^^^^^^^^^^^^^^^^^^^^^^^^^^^^^^^^^^^^^^^^^^^^^^
  File "/usr/src/homeassistant/homeassistant/config_entries.py", line 1500, in _async_init
    flow = await self.async_create_flow(handler, context=context, data=data)
           ^^^^^^^^^^^^^^^^^^^^^^^^^^^^^^^^^^^^^^^^^^^^^^^^^^^^^^^^^^^^^^^^^
  File "/usr/src/homeassistant/homeassistant/config_entries.py", line 1722, in async_create_flow
    handler = await _async_get_flow_handler(
              ^^^^^^^^^^^^^^^^^^^^^^^^^^^^^^
        self.hass, handler_key, self._hass_config
        ^^^^^^^^^^^^^^^^^^^^^^^^^^^^^^^^^^^^^^^^^
    )
    ^
  File "/usr/src/homeassistant/homeassistant/config_entries.py", line 3871, in _async_get_flow_handler
    await _load_integration(hass, domain, hass_config)
  File "/usr/src/homeassistant/homeassistant/config_entries.py", line 3848, in _load_integration
    await async_process_deps_reqs(hass, hass_config, integration)
  File "/usr/src/homeassistant/homeassistant/setup.py", line 584, in async_process_deps_reqs
    await requirements.async_get_integration_with_requirements(
        hass, integration.domain
    )
  File "/usr/src/homeassistant/homeassistant/requirements.py", line 54, in async_get_integration_with_requirements
    return await manager.async_get_integration_with_requirements(domain)
           ^^^^^^^^^^^^^^^^^^^^^^^^^^^^^^^^^^^^^^^^^^^^^^^^^^^^^^^^^^^^^
  File "/usr/src/homeassistant/homeassistant/requirements.py", line 170, in async_get_integration_with_requirements
    await future
  File "/usr/src/homeassistant/homeassistant/requirements.py", line 159, in async_get_integration_with_requirements
    await self._async_process_integration(integration, done)
  File "/usr/src/homeassistant/homeassistant/requirements.py", line 182, in _async_process_integration
    await self.async_process_requirements(
        integration.domain, integration.requirements
    )
  File "/usr/src/homeassistant/homeassistant/requirements.py", line 264, in async_process_requirements
    self._raise_for_failed_requirements(name, missing)
    ~~~~~~~~~~~~~~~~~~~~~~~~~~~~~~~~~~~^^^^^^^^^^^^^^^
  File "/usr/src/homeassistant/homeassistant/requirements.py", line 292, in _raise_for_failed_requirements
    raise RequirementsNotFound(integration, [req])
homeassistant.requirements.RequirementsNotFound: Requirements for spotifyplus not found: ['urllib3>=1.21.1,<1.27'].
2025-10-28 12:21:23.753 ERROR (MainThread) [deebot_client.mqtt_client.client] failed to receive on socket: [Errno 104] Connection reset by peer
2025-10-28 12:21:23.762 WARNING (MainThread) [deebot_client.mqtt_client] Connection lost; Reconnecting in 5 seconds ...
Traceback (most recent call last):
  File "/usr/local/lib/python3.13/site-packages/deebot_client/mqtt_client.py", line 201, in mqtt
    async with await self._get_client() as client:
               ^^^^^^^^^^^^^^^^^^^^^^^^
  File "/usr/local/lib/python3.13/site-packages/aiomqtt/client.py", line 792, in __aexit__
    raise exc
aiomqtt.exceptions.MqttCodeError: [code:128] Unspecified error
2025-10-28 12:22:11.095 ERROR (MainThread) [firebase_messaging.fcmpushclient] Unexpected exception during read
Traceback (most recent call last):
  File "/usr/local/lib/python3.13/site-packages/firebase_messaging/fcmpushclient.py", line 687, in _listen
    elif msg := await self._receive_msg():
                ^^^^^^^^^^^^^^^^^^^^^^^^^
  File "/usr/local/lib/python3.13/site-packages/firebase_messaging/fcmpushclient.py", line 300, in _receive_msg
    r = await self.reader.readexactly(1)  # type: ignore[union-attr]
        ^^^^^^^^^^^^^^^^^^^^^^^^^^^^^^^^
  File "/usr/local/lib/python3.13/asyncio/streams.py", line 758, in readexactly
    raise self._exception
  File "/usr/local/lib/python3.13/site-packages/firebase_messaging/fcmpushclient.py", line 210, in _do_writer_close
    await writer.wait_closed()
  File "/usr/local/lib/python3.13/asyncio/streams.py", line 358, in wait_closed
    await self._protocol._get_close_waiter(self)
TimeoutError: SSL shutdown timed out
2025-10-28 12:22:11.108 ERROR (MainThread) [firebase_messaging.fcmpushclient] Unexpected exception during read
Traceback (most recent call last):
  File "/usr/local/lib/python3.13/site-packages/firebase_messaging/fcmpushclient.py", line 687, in _listen
    elif msg := await self._receive_msg():
                ^^^^^^^^^^^^^^^^^^^^^^^^^
  File "/usr/local/lib/python3.13/site-packages/firebase_messaging/fcmpushclient.py", line 300, in _receive_msg
    r = await self.reader.readexactly(1)  # type: ignore[union-attr]
        ^^^^^^^^^^^^^^^^^^^^^^^^^^^^^^^^
  File "/usr/local/lib/python3.13/asyncio/streams.py", line 758, in readexactly
    raise self._exception
  File "/usr/local/lib/python3.13/site-packages/firebase_messaging/fcmpushclient.py", line 687, in _listen
    elif msg := await self._receive_msg():
                ^^^^^^^^^^^^^^^^^^^^^^^^^
  File "/usr/local/lib/python3.13/site-packages/firebase_messaging/fcmpushclient.py", line 300, in _receive_msg
    r = await self.reader.readexactly(1)  # type: ignore[union-attr]
        ^^^^^^^^^^^^^^^^^^^^^^^^^^^^^^^^
  File "/usr/local/lib/python3.13/asyncio/streams.py", line 758, in readexactly
    raise self._exception
  File "/usr/local/lib/python3.13/site-packages/firebase_messaging/fcmpushclient.py", line 210, in _do_writer_close
    await writer.wait_closed()
  File "/usr/local/lib/python3.13/asyncio/streams.py", line 358, in wait_closed
    await self._protocol._get_close_waiter(self)
TimeoutError: SSL shutdown timed out
2025-10-28 12:22:11.115 ERROR (MainThread) [firebase_messaging.fcmpushclient] Unexpected exception during read
Traceback (most recent call last):
  File "/usr/local/lib/python3.13/site-packages/firebase_messaging/fcmpushclient.py", line 687, in _listen
    elif msg := await self._receive_msg():
                ^^^^^^^^^^^^^^^^^^^^^^^^^
  File "/usr/local/lib/python3.13/site-packages/firebase_messaging/fcmpushclient.py", line 300, in _receive_msg
    r = await self.reader.readexactly(1)  # type: ignore[union-attr]
        ^^^^^^^^^^^^^^^^^^^^^^^^^^^^^^^^
  File "/usr/local/lib/python3.13/asyncio/streams.py", line 758, in readexactly
    raise self._exception
  File "/usr/local/lib/python3.13/site-packages/firebase_messaging/fcmpushclient.py", line 687, in _listen
    elif msg := await self._receive_msg():
                ^^^^^^^^^^^^^^^^^^^^^^^^^
  File "/usr/local/lib/python3.13/site-packages/firebase_messaging/fcmpushclient.py", line 300, in _receive_msg
    r = await self.reader.readexactly(1)  # type: ignore[union-attr]
        ^^^^^^^^^^^^^^^^^^^^^^^^^^^^^^^^
  File "/usr/local/lib/python3.13/asyncio/streams.py", line 758, in readexactly
    raise self._exception
  File "/usr/local/lib/python3.13/site-packages/firebase_messaging/fcmpushclient.py", line 687, in _listen
    elif msg := await self._receive_msg():
                ^^^^^^^^^^^^^^^^^^^^^^^^^
  File "/usr/local/lib/python3.13/site-packages/firebase_messaging/fcmpushclient.py", line 300, in _receive_msg
    r = await self.reader.readexactly(1)  # type: ignore[union-attr]
        ^^^^^^^^^^^^^^^^^^^^^^^^^^^^^^^^
  File "/usr/local/lib/python3.13/asyncio/streams.py", line 758, in readexactly
    raise self._exception
  File "/usr/local/lib/python3.13/site-packages/firebase_messaging/fcmpushclient.py", line 210, in _do_writer_close
    await writer.wait_closed()
  File "/usr/local/lib/python3.13/asyncio/streams.py", line 358, in wait_closed
    await self._protocol._get_close_waiter(self)
TimeoutError: SSL shutdown timed out
2025-10-28 12:22:11.121 ERROR (MainThread) [firebase_messaging.fcmpushclient] Shutting down push receiver due to 3 sequential errors of type ErrorType.CONNECTION
2025-10-28 12:22:55.799 ERROR (MainThread) [snitun.multiplexer.core] Timeout error while pinging peer
2025-10-28 12:22:58.212 ERROR (MainThread) [homeassistant.components.google_travel_time.sensor] Routes API is disabled for this API key
2025-10-28 12:23:12.014 WARNING (MainThread) [homeassistant.helpers.entity] Update of sensor.maxwinter200_gmail_com_enddatum_des_urlaubs is taking over 10 seconds
2025-10-28 12:23:13.333 ERROR (MainThread) [homeassistant.components.google_tasks.coordinator] Timeout fetching Google Tasks MTA1NTgwMDQ0MTAyODg1NTI0MDE6MDow data
2025-10-28 12:24:02.143 ERROR (MainThread) [homeassistant.helpers.entity] Update for sensor.maxwinter200_gmail_com_enddatum_des_urlaubs fails
Traceback (most recent call last):
  File "/usr/src/homeassistant/homeassistant/helpers/entity.py", line 963, in async_update_ha_state
    await self.async_device_update()
  File "/usr/src/homeassistant/homeassistant/helpers/entity.py", line 1314, in async_device_update
    await self.async_update()
  File "/usr/src/homeassistant/homeassistant/components/google_mail/sensor.py", line 45, in async_update
    data: dict = await self.hass.async_add_executor_job(settings.execute)
                 ^^^^^^^^^^^^^^^^^^^^^^^^^^^^^^^^^^^^^^^^^^^^^^^^^^^^^^^^
  File "/usr/local/lib/python3.13/concurrent/futures/thread.py", line 59, in run
    result = self.fn(*self.args, **self.kwargs)
  File "/usr/local/lib/python3.13/site-packages/googleapiclient/_helpers.py", line 130, in positional_wrapper
    return wrapped(*args, **kwargs)
  File "/usr/local/lib/python3.13/site-packages/googleapiclient/http.py", line 923, in execute
    resp, content = _retry_request(
                    ~~~~~~~~~~~~~~^
        http,
        ^^^^^
    ...<7 lines>...
        headers=self.headers,
        ^^^^^^^^^^^^^^^^^^^^^
    )
    ^
  File "/usr/local/lib/python3.13/site-packages/googleapiclient/http.py", line 222, in _retry_request
    raise exception
  File "/usr/local/lib/python3.13/site-packages/googleapiclient/http.py", line 191, in _retry_request
    resp, content = http.request(uri, method, *args, **kwargs)
                    ~~~~~~~~~~~~^^^^^^^^^^^^^^^^^^^^^^^^^^^^^^
  File "/usr/local/lib/python3.13/site-packages/google_auth_httplib2.py", line 218, in request
    response, content = self.http.request(
                        ~~~~~~~~~~~~~~~~~^
        uri,
        ^^^^
    ...<5 lines>...
        **kwargs
        ^^^^^^^^
    )
    ^
  File "/usr/local/lib/python3.13/site-packages/httplib2/__init__.py", line 1724, in request
    (response, content) = self._request(
                          ~~~~~~~~~~~~~^
        conn, authority, uri, request_uri, method, body, headers, redirections, cachekey,
        ^^^^^^^^^^^^^^^^^^^^^^^^^^^^^^^^^^^^^^^^^^^^^^^^^^^^^^^^^^^^^^^^^^^^^^^^^^^^^^^^^
    )
    ^
  File "/usr/local/lib/python3.13/site-packages/httplib2/__init__.py", line 1444, in _request
    (response, content) = self._conn_request(conn, request_uri, method, body, headers)
                          ~~~~~~~~~~~~~~~~~~^^^^^^^^^^^^^^^^^^^^^^^^^^^^^^^^^^^^^^^^^^
  File "/usr/local/lib/python3.13/site-packages/httplib2/__init__.py", line 1366, in _conn_request
    conn.connect()
    ~~~~~~~~~~~~^^
  File "/usr/local/lib/python3.13/site-packages/httplib2/__init__.py", line 1156, in connect
    sock.connect((self.host, self.port))
    ~~~~~~~~~~~~^^^^^^^^^^^^^^^^^^^^^^^^
TimeoutError: timed out
2025-10-28 12:24:20.238 ERROR (MainThread) [custom_components.google_fit] Error fetching google_fit data: Error communicating with API: 
2025-10-28 12:32:58.220 ERROR (MainThread) [homeassistant.components.google_travel_time.sensor] Routes API is disabled for this API key
2025-10-28 12:36:55.202 ERROR (MainThread) [homeassistant] Error doing job: Task exception was never retrieved (None)
Traceback (most recent call last):
  File "/usr/src/homeassistant/homeassistant/config_entries.py", line 1464, in async_init
    flow, result = await self._async_init(flow_id, handler, context, data)
                   ^^^^^^^^^^^^^^^^^^^^^^^^^^^^^^^^^^^^^^^^^^^^^^^^^^^^^^^
  File "/usr/src/homeassistant/homeassistant/config_entries.py", line 1500, in _async_init
    flow = await self.async_create_flow(handler, context=context, data=data)
           ^^^^^^^^^^^^^^^^^^^^^^^^^^^^^^^^^^^^^^^^^^^^^^^^^^^^^^^^^^^^^^^^^
  File "/usr/src/homeassistant/homeassistant/config_entries.py", line 1722, in async_create_flow
    handler = await _async_get_flow_handler(
              ^^^^^^^^^^^^^^^^^^^^^^^^^^^^^^
        self.hass, handler_key, self._hass_config
        ^^^^^^^^^^^^^^^^^^^^^^^^^^^^^^^^^^^^^^^^^
    )
    ^
  File "/usr/src/homeassistant/homeassistant/config_entries.py", line 3871, in _async_get_flow_handler
    await _load_integration(hass, domain, hass_config)
  File "/usr/src/homeassistant/homeassistant/config_entries.py", line 3848, in _load_integration
    await async_process_deps_reqs(hass, hass_config, integration)
  File "/usr/src/homeassistant/homeassistant/setup.py", line 584, in async_process_deps_reqs
    await requirements.async_get_integration_with_requirements(
        hass, integration.domain
    )
  File "/usr/src/homeassistant/homeassistant/requirements.py", line 54, in async_get_integration_with_requirements
    return await manager.async_get_integration_with_requirements(domain)
           ^^^^^^^^^^^^^^^^^^^^^^^^^^^^^^^^^^^^^^^^^^^^^^^^^^^^^^^^^^^^^
  File "/usr/src/homeassistant/homeassistant/requirements.py", line 170, in async_get_integration_with_requirements
    await future
  File "/usr/src/homeassistant/homeassistant/requirements.py", line 159, in async_get_integration_with_requirements
    await self._async_process_integration(integration, done)
  File "/usr/src/homeassistant/homeassistant/requirements.py", line 182, in _async_process_integration
    await self.async_process_requirements(
        integration.domain, integration.requirements
    )
  File "/usr/src/homeassistant/homeassistant/requirements.py", line 264, in async_process_requirements
    self._raise_for_failed_requirements(name, missing)
    ~~~~~~~~~~~~~~~~~~~~~~~~~~~~~~~~~~~^^^^^^^^^^^^^^^
  File "/usr/src/homeassistant/homeassistant/requirements.py", line 292, in _raise_for_failed_requirements
    raise RequirementsNotFound(integration, [req])
homeassistant.requirements.RequirementsNotFound: Requirements for spotifyplus not found: ['urllib3>=1.21.1,<1.27'].
2025-10-28 12:38:12.016 WARNING (MainThread) [homeassistant.helpers.entity] Update of sensor.maxwinter200_gmail_com_enddatum_des_urlaubs is taking over 10 seconds
2025-10-28 12:38:26.746 WARNING (MainThread) [deebot_client.command] No response received for command "getMapSet". This can happen if the device has network issues or does not support the command
2025-10-28 12:38:26.991 WARNING (MainThread) [deebot_client.command] No response received for command "getMapSubSet". This can happen if the device has network issues or does not support the command
2025-10-28 12:38:28.020 WARNING (MainThread) [deebot_client.command] No response received for command "getLifeSpan". This can happen if the device has network issues or does not support the command
2025-10-28 12:38:29.763 WARNING (MainThread) [deebot_client.command] No response received for command "getMapSubSet". This can happen if the device has network issues or does not support the command
2025-10-28 12:39:02.137 ERROR (MainThread) [homeassistant.helpers.entity] Update for sensor.maxwinter200_gmail_com_enddatum_des_urlaubs fails
Traceback (most recent call last):
  File "/usr/src/homeassistant/homeassistant/helpers/entity.py", line 963, in async_update_ha_state
    await self.async_device_update()
  File "/usr/src/homeassistant/homeassistant/helpers/entity.py", line 1314, in async_device_update
    await self.async_update()
  File "/usr/src/homeassistant/homeassistant/components/google_mail/sensor.py", line 45, in async_update
    data: dict = await self.hass.async_add_executor_job(settings.execute)
                 ^^^^^^^^^^^^^^^^^^^^^^^^^^^^^^^^^^^^^^^^^^^^^^^^^^^^^^^^
  File "/usr/local/lib/python3.13/concurrent/futures/thread.py", line 59, in run
    result = self.fn(*self.args, **self.kwargs)
  File "/usr/local/lib/python3.13/site-packages/googleapiclient/_helpers.py", line 130, in positional_wrapper
    return wrapped(*args, **kwargs)
  File "/usr/local/lib/python3.13/site-packages/googleapiclient/http.py", line 923, in execute
    resp, content = _retry_request(
                    ~~~~~~~~~~~~~~^
        http,
        ^^^^^
    ...<7 lines>...
        headers=self.headers,
        ^^^^^^^^^^^^^^^^^^^^^
    )
    ^
  File "/usr/local/lib/python3.13/site-packages/googleapiclient/http.py", line 222, in _retry_request
    raise exception
  File "/usr/local/lib/python3.13/site-packages/googleapiclient/http.py", line 191, in _retry_request
    resp, content = http.request(uri, method, *args, **kwargs)
                    ~~~~~~~~~~~~^^^^^^^^^^^^^^^^^^^^^^^^^^^^^^
  File "/usr/local/lib/python3.13/site-packages/google_auth_httplib2.py", line 218, in request
    response, content = self.http.request(
                        ~~~~~~~~~~~~~~~~~^
        uri,
        ^^^^
    ...<5 lines>...
        **kwargs
        ^^^^^^^^
    )
    ^
  File "/usr/local/lib/python3.13/site-packages/httplib2/__init__.py", line 1724, in request
    (response, content) = self._request(
                          ~~~~~~~~~~~~~^
        conn, authority, uri, request_uri, method, body, headers, redirections, cachekey,
        ^^^^^^^^^^^^^^^^^^^^^^^^^^^^^^^^^^^^^^^^^^^^^^^^^^^^^^^^^^^^^^^^^^^^^^^^^^^^^^^^^
    )
    ^
  File "/usr/local/lib/python3.13/site-packages/httplib2/__init__.py", line 1444, in _request
    (response, content) = self._conn_request(conn, request_uri, method, body, headers)
                          ~~~~~~~~~~~~~~~~~~^^^^^^^^^^^^^^^^^^^^^^^^^^^^^^^^^^^^^^^^^^
  File "/usr/local/lib/python3.13/site-packages/httplib2/__init__.py", line 1366, in _conn_request
    conn.connect()
    ~~~~~~~~~~~~^^
  File "/usr/local/lib/python3.13/site-packages/httplib2/__init__.py", line 1156, in connect
    sock.connect((self.host, self.port))
    ~~~~~~~~~~~~^^^^^^^^^^^^^^^^^^^^^^^^
TimeoutError: timed out
2025-10-28 12:42:57.970 ERROR (MainThread) [homeassistant.components.google_travel_time.sensor] Routes API is disabled for this API key
2025-10-28 12:50:10.379 ERROR (Recorder) [homeassistant] Error doing job: Task exception was never retrieved (None)
Traceback (most recent call last):
  File "/usr/src/homeassistant/homeassistant/config_entries.py", line 1464, in async_init
    flow, result = await self._async_init(flow_id, handler, context, data)
                   ^^^^^^^^^^^^^^^^^^^^^^^^^^^^^^^^^^^^^^^^^^^^^^^^^^^^^^^
  File "/usr/src/homeassistant/homeassistant/config_entries.py", line 1500, in _async_init
    flow = await self.async_create_flow(handler, context=context, data=data)
           ^^^^^^^^^^^^^^^^^^^^^^^^^^^^^^^^^^^^^^^^^^^^^^^^^^^^^^^^^^^^^^^^^
  File "/usr/src/homeassistant/homeassistant/config_entries.py", line 1722, in async_create_flow
    handler = await _async_get_flow_handler(
              ^^^^^^^^^^^^^^^^^^^^^^^^^^^^^^
        self.hass, handler_key, self._hass_config
        ^^^^^^^^^^^^^^^^^^^^^^^^^^^^^^^^^^^^^^^^^
    )
    ^
  File "/usr/src/homeassistant/homeassistant/config_entries.py", line 3871, in _async_get_flow_handler
    await _load_integration(hass, domain, hass_config)
  File "/usr/src/homeassistant/homeassistant/config_entries.py", line 3848, in _load_integration
    await async_process_deps_reqs(hass, hass_config, integration)
  File "/usr/src/homeassistant/homeassistant/setup.py", line 584, in async_process_deps_reqs
    await requirements.async_get_integration_with_requirements(
        hass, integration.domain
    )
  File "/usr/src/homeassistant/homeassistant/requirements.py", line 54, in async_get_integration_with_requirements
    return await manager.async_get_integration_with_requirements(domain)
           ^^^^^^^^^^^^^^^^^^^^^^^^^^^^^^^^^^^^^^^^^^^^^^^^^^^^^^^^^^^^^
  File "/usr/src/homeassistant/homeassistant/requirements.py", line 170, in async_get_integration_with_requirements
    await future
  File "/usr/src/homeassistant/homeassistant/requirements.py", line 159, in async_get_integration_with_requirements
    await self._async_process_integration(integration, done)
  File "/usr/src/homeassistant/homeassistant/requirements.py", line 182, in _async_process_integration
    await self.async_process_requirements(
        integration.domain, integration.requirements
    )
  File "/usr/src/homeassistant/homeassistant/requirements.py", line 264, in async_process_requirements
    self._raise_for_failed_requirements(name, missing)
    ~~~~~~~~~~~~~~~~~~~~~~~~~~~~~~~~~~~^^^^^^^^^^^^^^^
  File "/usr/src/homeassistant/homeassistant/requirements.py", line 292, in _raise_for_failed_requirements
    raise RequirementsNotFound(integration, [req])
homeassistant.requirements.RequirementsNotFound: Requirements for spotifyplus not found: ['urllib3>=1.21.1,<1.27'].
2025-10-28 12:52:57.967 ERROR (MainThread) [homeassistant.components.google_travel_time.sensor] Routes API is disabled for this API key
2025-10-28 13:02:57.973 ERROR (MainThread) [homeassistant.components.google_travel_time.sensor] Routes API is disabled for this API key
2025-10-28 13:04:34.047 ERROR (MainThread) [homeassistant] Error doing job: Task exception was never retrieved (None)
Traceback (most recent call last):
  File "/usr/src/homeassistant/homeassistant/config_entries.py", line 1464, in async_init
    flow, result = await self._async_init(flow_id, handler, context, data)
                   ^^^^^^^^^^^^^^^^^^^^^^^^^^^^^^^^^^^^^^^^^^^^^^^^^^^^^^^
  File "/usr/src/homeassistant/homeassistant/config_entries.py", line 1500, in _async_init
    flow = await self.async_create_flow(handler, context=context, data=data)
           ^^^^^^^^^^^^^^^^^^^^^^^^^^^^^^^^^^^^^^^^^^^^^^^^^^^^^^^^^^^^^^^^^
  File "/usr/src/homeassistant/homeassistant/config_entries.py", line 1722, in async_create_flow
    handler = await _async_get_flow_handler(
              ^^^^^^^^^^^^^^^^^^^^^^^^^^^^^^
        self.hass, handler_key, self._hass_config
        ^^^^^^^^^^^^^^^^^^^^^^^^^^^^^^^^^^^^^^^^^
    )
    ^
  File "/usr/src/homeassistant/homeassistant/config_entries.py", line 3871, in _async_get_flow_handler
    await _load_integration(hass, domain, hass_config)
  File "/usr/src/homeassistant/homeassistant/config_entries.py", line 3848, in _load_integration
    await async_process_deps_reqs(hass, hass_config, integration)
  File "/usr/src/homeassistant/homeassistant/setup.py", line 584, in async_process_deps_reqs
    await requirements.async_get_integration_with_requirements(
        hass, integration.domain
    )
  File "/usr/src/homeassistant/homeassistant/requirements.py", line 54, in async_get_integration_with_requirements
    return await manager.async_get_integration_with_requirements(domain)
           ^^^^^^^^^^^^^^^^^^^^^^^^^^^^^^^^^^^^^^^^^^^^^^^^^^^^^^^^^^^^^
  File "/usr/src/homeassistant/homeassistant/requirements.py", line 170, in async_get_integration_with_requirements
    await future
  File "/usr/src/homeassistant/homeassistant/requirements.py", line 159, in async_get_integration_with_requirements
    await self._async_process_integration(integration, done)
  File "/usr/src/homeassistant/homeassistant/requirements.py", line 182, in _async_process_integration
    await self.async_process_requirements(
        integration.domain, integration.requirements
    )
  File "/usr/src/homeassistant/homeassistant/requirements.py", line 264, in async_process_requirements
    self._raise_for_failed_requirements(name, missing)
    ~~~~~~~~~~~~~~~~~~~~~~~~~~~~~~~~~~~^^^^^^^^^^^^^^^
  File "/usr/src/homeassistant/homeassistant/requirements.py", line 292, in _raise_for_failed_requirements
    raise RequirementsNotFound(integration, [req])
homeassistant.requirements.RequirementsNotFound: Requirements for spotifyplus not found: ['urllib3>=1.21.1,<1.27'].
2025-10-28 13:12:57.963 ERROR (MainThread) [homeassistant.components.google_travel_time.sensor] Routes API is disabled for this API key
2025-10-28 13:19:53.164 ERROR (Thread-6) [homeassistant] Error doing job: Task exception was never retrieved (None)
Traceback (most recent call last):
  File "/usr/src/homeassistant/homeassistant/config_entries.py", line 1464, in async_init
    flow, result = await self._async_init(flow_id, handler, context, data)
                   ^^^^^^^^^^^^^^^^^^^^^^^^^^^^^^^^^^^^^^^^^^^^^^^^^^^^^^^
  File "/usr/src/homeassistant/homeassistant/config_entries.py", line 1500, in _async_init
    flow = await self.async_create_flow(handler, context=context, data=data)
           ^^^^^^^^^^^^^^^^^^^^^^^^^^^^^^^^^^^^^^^^^^^^^^^^^^^^^^^^^^^^^^^^^
  File "/usr/src/homeassistant/homeassistant/config_entries.py", line 1722, in async_create_flow
    handler = await _async_get_flow_handler(
              ^^^^^^^^^^^^^^^^^^^^^^^^^^^^^^
        self.hass, handler_key, self._hass_config
        ^^^^^^^^^^^^^^^^^^^^^^^^^^^^^^^^^^^^^^^^^
    )
    ^
  File "/usr/src/homeassistant/homeassistant/config_entries.py", line 3871, in _async_get_flow_handler
    await _load_integration(hass, domain, hass_config)
  File "/usr/src/homeassistant/homeassistant/config_entries.py", line 3848, in _load_integration
    await async_process_deps_reqs(hass, hass_config, integration)
  File "/usr/src/homeassistant/homeassistant/setup.py", line 584, in async_process_deps_reqs
    await requirements.async_get_integration_with_requirements(
        hass, integration.domain
    )
  File "/usr/src/homeassistant/homeassistant/requirements.py", line 54, in async_get_integration_with_requirements
    return await manager.async_get_integration_with_requirements(domain)
           ^^^^^^^^^^^^^^^^^^^^^^^^^^^^^^^^^^^^^^^^^^^^^^^^^^^^^^^^^^^^^
  File "/usr/src/homeassistant/homeassistant/requirements.py", line 170, in async_get_integration_with_requirements
    await future
  File "/usr/src/homeassistant/homeassistant/requirements.py", line 159, in async_get_integration_with_requirements
    await self._async_process_integration(integration, done)
  File "/usr/src/homeassistant/homeassistant/requirements.py", line 182, in _async_process_integration
    await self.async_process_requirements(
        integration.domain, integration.requirements
    )
  File "/usr/src/homeassistant/homeassistant/requirements.py", line 264, in async_process_requirements
    self._raise_for_failed_requirements(name, missing)
    ~~~~~~~~~~~~~~~~~~~~~~~~~~~~~~~~~~~^^^^^^^^^^^^^^^
  File "/usr/src/homeassistant/homeassistant/requirements.py", line 292, in _raise_for_failed_requirements
    raise RequirementsNotFound(integration, [req])
homeassistant.requirements.RequirementsNotFound: Requirements for spotifyplus not found: ['urllib3>=1.21.1,<1.27'].
2025-10-28 13:22:57.968 ERROR (MainThread) [homeassistant.components.google_travel_time.sensor] Routes API is disabled for this API key
2025-10-28 13:31:55.199 ERROR (MainThread) [homeassistant] Error doing job: Task exception was never retrieved (None)
Traceback (most recent call last):
  File "/usr/src/homeassistant/homeassistant/config_entries.py", line 1464, in async_init
    flow, result = await self._async_init(flow_id, handler, context, data)
                   ^^^^^^^^^^^^^^^^^^^^^^^^^^^^^^^^^^^^^^^^^^^^^^^^^^^^^^^
  File "/usr/src/homeassistant/homeassistant/config_entries.py", line 1500, in _async_init
    flow = await self.async_create_flow(handler, context=context, data=data)
           ^^^^^^^^^^^^^^^^^^^^^^^^^^^^^^^^^^^^^^^^^^^^^^^^^^^^^^^^^^^^^^^^^
  File "/usr/src/homeassistant/homeassistant/config_entries.py", line 1722, in async_create_flow
    handler = await _async_get_flow_handler(
              ^^^^^^^^^^^^^^^^^^^^^^^^^^^^^^
        self.hass, handler_key, self._hass_config
        ^^^^^^^^^^^^^^^^^^^^^^^^^^^^^^^^^^^^^^^^^
    )
    ^
  File "/usr/src/homeassistant/homeassistant/config_entries.py", line 3871, in _async_get_flow_handler
    await _load_integration(hass, domain, hass_config)
  File "/usr/src/homeassistant/homeassistant/config_entries.py", line 3848, in _load_integration
    await async_process_deps_reqs(hass, hass_config, integration)
  File "/usr/src/homeassistant/homeassistant/setup.py", line 584, in async_process_deps_reqs
    await requirements.async_get_integration_with_requirements(
        hass, integration.domain
    )
  File "/usr/src/homeassistant/homeassistant/requirements.py", line 54, in async_get_integration_with_requirements
    return await manager.async_get_integration_with_requirements(domain)
           ^^^^^^^^^^^^^^^^^^^^^^^^^^^^^^^^^^^^^^^^^^^^^^^^^^^^^^^^^^^^^
  File "/usr/src/homeassistant/homeassistant/requirements.py", line 170, in async_get_integration_with_requirements
    await future
  File "/usr/src/homeassistant/homeassistant/requirements.py", line 159, in async_get_integration_with_requirements
    await self._async_process_integration(integration, done)
  File "/usr/src/homeassistant/homeassistant/requirements.py", line 182, in _async_process_integration
    await self.async_process_requirements(
        integration.domain, integration.requirements
    )
  File "/usr/src/homeassistant/homeassistant/requirements.py", line 264, in async_process_requirements
    self._raise_for_failed_requirements(name, missing)
    ~~~~~~~~~~~~~~~~~~~~~~~~~~~~~~~~~~~^^^^^^^^^^^^^^^
  File "/usr/src/homeassistant/homeassistant/requirements.py", line 292, in _raise_for_failed_requirements
    raise RequirementsNotFound(integration, [req])
homeassistant.requirements.RequirementsNotFound: Requirements for spotifyplus not found: ['urllib3>=1.21.1,<1.27'].
2025-10-28 13:32:57.965 ERROR (MainThread) [homeassistant.components.google_travel_time.sensor] Routes API is disabled for this API key
2025-10-28 13:41:06.610 WARNING (MainThread) [deebot_client.command] No response received for command "getTotalStats". This can happen if the device has network issues or does not support the command
2025-10-28 13:42:57.968 ERROR (MainThread) [homeassistant.components.google_travel_time.sensor] Routes API is disabled for this API key
2025-10-28 13:46:18.390 ERROR (SyncWorker_0) [homeassistant] Error doing job: Task exception was never retrieved (None)
Traceback (most recent call last):
  File "/usr/src/homeassistant/homeassistant/config_entries.py", line 1464, in async_init
    flow, result = await self._async_init(flow_id, handler, context, data)
                   ^^^^^^^^^^^^^^^^^^^^^^^^^^^^^^^^^^^^^^^^^^^^^^^^^^^^^^^
  File "/usr/src/homeassistant/homeassistant/config_entries.py", line 1500, in _async_init
    flow = await self.async_create_flow(handler, context=context, data=data)
           ^^^^^^^^^^^^^^^^^^^^^^^^^^^^^^^^^^^^^^^^^^^^^^^^^^^^^^^^^^^^^^^^^
  File "/usr/src/homeassistant/homeassistant/config_entries.py", line 1722, in async_create_flow
    handler = await _async_get_flow_handler(
              ^^^^^^^^^^^^^^^^^^^^^^^^^^^^^^
        self.hass, handler_key, self._hass_config
        ^^^^^^^^^^^^^^^^^^^^^^^^^^^^^^^^^^^^^^^^^
    )
    ^
  File "/usr/src/homeassistant/homeassistant/config_entries.py", line 3871, in _async_get_flow_handler
    await _load_integration(hass, domain, hass_config)
  File "/usr/src/homeassistant/homeassistant/config_entries.py", line 3848, in _load_integration
    await async_process_deps_reqs(hass, hass_config, integration)
  File "/usr/src/homeassistant/homeassistant/setup.py", line 584, in async_process_deps_reqs
    await requirements.async_get_integration_with_requirements(
        hass, integration.domain
    )
  File "/usr/src/homeassistant/homeassistant/requirements.py", line 54, in async_get_integration_with_requirements
    return await manager.async_get_integration_with_requirements(domain)
           ^^^^^^^^^^^^^^^^^^^^^^^^^^^^^^^^^^^^^^^^^^^^^^^^^^^^^^^^^^^^^
  File "/usr/src/homeassistant/homeassistant/requirements.py", line 170, in async_get_integration_with_requirements
    await future
  File "/usr/src/homeassistant/homeassistant/requirements.py", line 159, in async_get_integration_with_requirements
    await self._async_process_integration(integration, done)
  File "/usr/src/homeassistant/homeassistant/requirements.py", line 182, in _async_process_integration
    await self.async_process_requirements(
        integration.domain, integration.requirements
    )
  File "/usr/src/homeassistant/homeassistant/requirements.py", line 264, in async_process_requirements
    self._raise_for_failed_requirements(name, missing)
    ~~~~~~~~~~~~~~~~~~~~~~~~~~~~~~~~~~~^^^^^^^^^^^^^^^
  File "/usr/src/homeassistant/homeassistant/requirements.py", line 292, in _raise_for_failed_requirements
    raise RequirementsNotFound(integration, [req])
homeassistant.requirements.RequirementsNotFound: Requirements for spotifyplus not found: ['urllib3>=1.21.1,<1.27'].
2025-10-28 13:52:57.960 ERROR (MainThread) [homeassistant.components.google_travel_time.sensor] Routes API is disabled for this API key
2025-10-28 13:58:28.974 WARNING (MainThread) [deebot_client.command] No response received for command "getPos". This can happen if the device has network issues or does not support the command
2025-10-28 13:58:29.960 WARNING (MainThread) [deebot_client.command] No response received for command "getMapSubSet". This can happen if the device has network issues or does not support the command
2025-10-28 13:58:38.760 WARNING (MainThread) [deebot_client.command] No response received for command "getMapSubSet". This can happen if the device has network issues or does not support the command
2025-10-28 14:00:10.386 ERROR (Recorder) [homeassistant] Error doing job: Task exception was never retrieved (None)
Traceback (most recent call last):
  File "/usr/src/homeassistant/homeassistant/config_entries.py", line 1464, in async_init
    flow, result = await self._async_init(flow_id, handler, context, data)
                   ^^^^^^^^^^^^^^^^^^^^^^^^^^^^^^^^^^^^^^^^^^^^^^^^^^^^^^^
  File "/usr/src/homeassistant/homeassistant/config_entries.py", line 1500, in _async_init
    flow = await self.async_create_flow(handler, context=context, data=data)
           ^^^^^^^^^^^^^^^^^^^^^^^^^^^^^^^^^^^^^^^^^^^^^^^^^^^^^^^^^^^^^^^^^
  File "/usr/src/homeassistant/homeassistant/config_entries.py", line 1722, in async_create_flow
    handler = await _async_get_flow_handler(
              ^^^^^^^^^^^^^^^^^^^^^^^^^^^^^^
        self.hass, handler_key, self._hass_config
        ^^^^^^^^^^^^^^^^^^^^^^^^^^^^^^^^^^^^^^^^^
    )
    ^
  File "/usr/src/homeassistant/homeassistant/config_entries.py", line 3871, in _async_get_flow_handler
    await _load_integration(hass, domain, hass_config)
  File "/usr/src/homeassistant/homeassistant/config_entries.py", line 3848, in _load_integration
    await async_process_deps_reqs(hass, hass_config, integration)
  File "/usr/src/homeassistant/homeassistant/setup.py", line 584, in async_process_deps_reqs
    await requirements.async_get_integration_with_requirements(
        hass, integration.domain
    )
  File "/usr/src/homeassistant/homeassistant/requirements.py", line 54, in async_get_integration_with_requirements
    return await manager.async_get_integration_with_requirements(domain)
           ^^^^^^^^^^^^^^^^^^^^^^^^^^^^^^^^^^^^^^^^^^^^^^^^^^^^^^^^^^^^^
  File "/usr/src/homeassistant/homeassistant/requirements.py", line 170, in async_get_integration_with_requirements
    await future
  File "/usr/src/homeassistant/homeassistant/requirements.py", line 159, in async_get_integration_with_requirements
    await self._async_process_integration(integration, done)
  File "/usr/src/homeassistant/homeassistant/requirements.py", line 182, in _async_process_integration
    await self.async_process_requirements(
        integration.domain, integration.requirements
    )
  File "/usr/src/homeassistant/homeassistant/requirements.py", line 264, in async_process_requirements
    self._raise_for_failed_requirements(name, missing)
    ~~~~~~~~~~~~~~~~~~~~~~~~~~~~~~~~~~~^^^^^^^^^^^^^^^
  File "/usr/src/homeassistant/homeassistant/requirements.py", line 292, in _raise_for_failed_requirements
    raise RequirementsNotFound(integration, [req])
homeassistant.requirements.RequirementsNotFound: Requirements for spotifyplus not found: ['urllib3>=1.21.1,<1.27'].
2025-10-28 14:02:57.968 ERROR (MainThread) [homeassistant.components.google_travel_time.sensor] Routes API is disabled for this API key
2025-10-28 14:12:57.967 ERROR (MainThread) [homeassistant.components.google_travel_time.sensor] Routes API is disabled for this API key
2025-10-28 14:13:57.503 ERROR (MainThread) [homeassistant] Error doing job: Task exception was never retrieved (None)
Traceback (most recent call last):
  File "/usr/src/homeassistant/homeassistant/config_entries.py", line 1464, in async_init
    flow, result = await self._async_init(flow_id, handler, context, data)
                   ^^^^^^^^^^^^^^^^^^^^^^^^^^^^^^^^^^^^^^^^^^^^^^^^^^^^^^^
  File "/usr/src/homeassistant/homeassistant/config_entries.py", line 1500, in _async_init
    flow = await self.async_create_flow(handler, context=context, data=data)
           ^^^^^^^^^^^^^^^^^^^^^^^^^^^^^^^^^^^^^^^^^^^^^^^^^^^^^^^^^^^^^^^^^
  File "/usr/src/homeassistant/homeassistant/config_entries.py", line 1722, in async_create_flow
    handler = await _async_get_flow_handler(
              ^^^^^^^^^^^^^^^^^^^^^^^^^^^^^^
        self.hass, handler_key, self._hass_config
        ^^^^^^^^^^^^^^^^^^^^^^^^^^^^^^^^^^^^^^^^^
    )
    ^
  File "/usr/src/homeassistant/homeassistant/config_entries.py", line 3871, in _async_get_flow_handler
    await _load_integration(hass, domain, hass_config)
  File "/usr/src/homeassistant/homeassistant/config_entries.py", line 3848, in _load_integration
    await async_process_deps_reqs(hass, hass_config, integration)
  File "/usr/src/homeassistant/homeassistant/setup.py", line 584, in async_process_deps_reqs
    await requirements.async_get_integration_with_requirements(
        hass, integration.domain
    )
  File "/usr/src/homeassistant/homeassistant/requirements.py", line 54, in async_get_integration_with_requirements
    return await manager.async_get_integration_with_requirements(domain)
           ^^^^^^^^^^^^^^^^^^^^^^^^^^^^^^^^^^^^^^^^^^^^^^^^^^^^^^^^^^^^^
  File "/usr/src/homeassistant/homeassistant/requirements.py", line 170, in async_get_integration_with_requirements
    await future
  File "/usr/src/homeassistant/homeassistant/requirements.py", line 159, in async_get_integration_with_requirements
    await self._async_process_integration(integration, done)
  File "/usr/src/homeassistant/homeassistant/requirements.py", line 182, in _async_process_integration
    await self.async_process_requirements(
        integration.domain, integration.requirements
    )
  File "/usr/src/homeassistant/homeassistant/requirements.py", line 264, in async_process_requirements
    self._raise_for_failed_requirements(name, missing)
    ~~~~~~~~~~~~~~~~~~~~~~~~~~~~~~~~~~~^^^^^^^^^^^^^^^
  File "/usr/src/homeassistant/homeassistant/requirements.py", line 292, in _raise_for_failed_requirements
    raise RequirementsNotFound(integration, [req])
homeassistant.requirements.RequirementsNotFound: Requirements for spotifyplus not found: ['urllib3>=1.21.1,<1.27'].
2025-10-28 14:15:38.333 ERROR (MainThread) [frontend.js.modern.202510014] Uncaught error from Chrome 141.0.0.0 on Windows 10
Error: Failed to execute 'define' on 'CustomElementRegistry': the name "swipe-card" has already been used with this registry
A.define (node_modules/@webcomponents/scoped-custom-element-registry/src/scoped-custom-element-registry.ts:180:12)
a.define (/hacsfiles/tabbed-card/tabbed-card.js:63:109)
/hacsfiles/swipe-card/swipe-card.js:1:183661
2025-10-28 14:15:38.334 ERROR (MainThread) [frontend.js.modern.202510014] Uncaught error from Chrome 141.0.0.0 on Windows 10
Error: Failed to execute 'define' on 'CustomElementRegistry': the name "button-card-action-handler" has already been used with this registry
A.define (node_modules/@webcomponents/scoped-custom-element-registry/src/scoped-custom-element-registry.ts:180:12)
a.define (/hacsfiles/tabbed-card/tabbed-card.js:63:109)
/hacsfiles/button-card/button-card.js:1:26705
2025-10-28 14:22:57.977 ERROR (MainThread) [homeassistant.components.google_travel_time.sensor] Routes API is disabled for this API key
2025-10-28 14:26:57.847 ERROR (MainThread) [frontend.js.modern.202510014] Uncaught error from Chrome WebView 142.0.7444.48 on Android 14
Error: Failed to execute 'define' on 'CustomElementRegistry': the name "swipe-card" has already been used with this registry
A.define (node_modules/@webcomponents/scoped-custom-element-registry/src/scoped-custom-element-registry.ts:180:12)
a.define (/hacsfiles/tabbed-card/tabbed-card.js:63:109)
/gh/bramkragten/custom-ui@master/swipe-card/swipe-card.js:1:173638
/gh/bramkragten/custom-ui@master/swipe-card/swipe-card.js:1:121
/gh/bramkragten/custom-ui@master/swipe-card/swipe-card.js:1:125
2025-10-28 14:26:57.848 ERROR (MainThread) [frontend.js.modern.202510014] Uncaught error from Chrome WebView 142.0.7444.48 on Android 14
Error: Failed to execute 'define' on 'CustomElementRegistry': the name "button-card-action-handler" has already been used with this registry
A.define (node_modules/@webcomponents/scoped-custom-element-registry/src/scoped-custom-element-registry.ts:180:12)
a.define (/hacsfiles/tabbed-card/tabbed-card.js:63:109)
/hacsfiles/button-card/button-card.js:1:26895
2025-10-28 14:28:28.967 ERROR (SyncWorker_6) [homeassistant] Error doing job: Task exception was never retrieved (None)
Traceback (most recent call last):
  File "/usr/src/homeassistant/homeassistant/config_entries.py", line 1464, in async_init
    flow, result = await self._async_init(flow_id, handler, context, data)
                   ^^^^^^^^^^^^^^^^^^^^^^^^^^^^^^^^^^^^^^^^^^^^^^^^^^^^^^^
  File "/usr/src/homeassistant/homeassistant/config_entries.py", line 1500, in _async_init
    flow = await self.async_create_flow(handler, context=context, data=data)
           ^^^^^^^^^^^^^^^^^^^^^^^^^^^^^^^^^^^^^^^^^^^^^^^^^^^^^^^^^^^^^^^^^
  File "/usr/src/homeassistant/homeassistant/config_entries.py", line 1722, in async_create_flow
    handler = await _async_get_flow_handler(
              ^^^^^^^^^^^^^^^^^^^^^^^^^^^^^^
        self.hass, handler_key, self._hass_config
        ^^^^^^^^^^^^^^^^^^^^^^^^^^^^^^^^^^^^^^^^^
    )
    ^
  File "/usr/src/homeassistant/homeassistant/config_entries.py", line 3871, in _async_get_flow_handler
    await _load_integration(hass, domain, hass_config)
  File "/usr/src/homeassistant/homeassistant/config_entries.py", line 3848, in _load_integration
    await async_process_deps_reqs(hass, hass_config, integration)
  File "/usr/src/homeassistant/homeassistant/setup.py", line 584, in async_process_deps_reqs
    await requirements.async_get_integration_with_requirements(
        hass, integration.domain
    )
  File "/usr/src/homeassistant/homeassistant/requirements.py", line 54, in async_get_integration_with_requirements
    return await manager.async_get_integration_with_requirements(domain)
           ^^^^^^^^^^^^^^^^^^^^^^^^^^^^^^^^^^^^^^^^^^^^^^^^^^^^^^^^^^^^^
  File "/usr/src/homeassistant/homeassistant/requirements.py", line 170, in async_get_integration_with_requirements
    await future
  File "/usr/src/homeassistant/homeassistant/requirements.py", line 159, in async_get_integration_with_requirements
    await self._async_process_integration(integration, done)
  File "/usr/src/homeassistant/homeassistant/requirements.py", line 182, in _async_process_integration
    await self.async_process_requirements(
        integration.domain, integration.requirements
    )
  File "/usr/src/homeassistant/homeassistant/requirements.py", line 264, in async_process_requirements
    self._raise_for_failed_requirements(name, missing)
    ~~~~~~~~~~~~~~~~~~~~~~~~~~~~~~~~~~~^^^^^^^^^^^^^^^
  File "/usr/src/homeassistant/homeassistant/requirements.py", line 292, in _raise_for_failed_requirements
    raise RequirementsNotFound(integration, [req])
homeassistant.requirements.RequirementsNotFound: Requirements for spotifyplus not found: ['urllib3>=1.21.1,<1.27'].
2025-10-28 14:28:30.335 ERROR (MainThread) [homeassistant.config] Invalid config for 'template' at configuration.yaml, line 32: 'scan_interval' is an invalid option for 'template', check: sensor->0->scan_interval
2025-10-28 14:28:30.336 ERROR (MainThread) [homeassistant.config] Invalid config for 'template' at configuration.yaml, line 104: expected BinarySensorDeviceClass or one of 'battery', 'battery_charging', 'carbon_monoxide', 'cold', 'connectivity', 'door', 'garage_door', 'gas', 'heat', 'light', 'lock', 'moisture', 'motion', 'moving', 'occupancy', 'opening', 'plug', 'power', 'presence', 'problem', 'running', 'safety', 'smoke', 'sound', 'tamper', 'update', 'vibration', 'window' for dictionary value 'binary_sensor->0->device_class', got 'doorbell'
2025-10-28 14:28:32.573 ERROR (MainThread) [homeassistant.config] Invalid config for 'template' at configuration.yaml, line 32: 'scan_interval' is an invalid option for 'template', check: sensor->0->scan_interval
2025-10-28 14:28:32.574 ERROR (MainThread) [homeassistant.config] Invalid config for 'template' at configuration.yaml, line 104: expected BinarySensorDeviceClass or one of 'battery', 'battery_charging', 'carbon_monoxide', 'cold', 'connectivity', 'door', 'garage_door', 'gas', 'heat', 'light', 'lock', 'moisture', 'motion', 'moving', 'occupancy', 'opening', 'plug', 'power', 'presence', 'problem', 'running', 'safety', 'smoke', 'sound', 'tamper', 'update', 'vibration', 'window' for dictionary value 'binary_sensor->0->device_class', got 'doorbell'
2025-10-28 14:28:39.978 ERROR (MainThread) [homeassistant.config] Invalid config for 'template' at configuration.yaml, line 32: 'scan_interval' is an invalid option for 'template', check: sensor->0->scan_interval
2025-10-28 14:28:39.979 ERROR (MainThread) [homeassistant.config] Invalid config for 'template' at configuration.yaml, line 104: expected BinarySensorDeviceClass or one of 'battery', 'battery_charging', 'carbon_monoxide', 'cold', 'connectivity', 'door', 'garage_door', 'gas', 'heat', 'light', 'lock', 'moisture', 'motion', 'moving', 'occupancy', 'opening', 'plug', 'power', 'presence', 'problem', 'running', 'safety', 'smoke', 'sound', 'tamper', 'update', 'vibration', 'window' for dictionary value 'binary_sensor->0->device_class', got 'doorbell'
2025-10-28 14:28:40.155 ERROR (MainThread) [homeassistant.config_entries] Error setting up entry 智能遥控 for broadlink
Traceback (most recent call last):
  File "/usr/src/homeassistant/homeassistant/config_entries.py", line 761, in __async_setup_with_context
    result = await component.async_setup_entry(hass, self)
             ^^^^^^^^^^^^^^^^^^^^^^^^^^^^^^^^^^^^^^^^^^^^^
  File "/usr/src/homeassistant/homeassistant/components/broadlink/__init__.py", line 39, in async_setup_entry
    if not await device.async_setup():
           ^^^^^^^^^^^^^^^^^^^^^^^^^^
  File "/usr/src/homeassistant/homeassistant/components/broadlink/device.py", line 112, in async_setup
    self.fw_version = await self.hass.async_add_executor_job(
                      ^^^^^^^^^^^^^^^^^^^^^^^^^^^^^^^^^^^^^^^
        self._get_firmware_version
        ^^^^^^^^^^^^^^^^^^^^^^^^^^
    )
    ^
asyncio.exceptions.CancelledError: Home Assistant is stopping
